Workbook

Sheet Form127_Raw
A1: Airport_Code | B1: Airport_Name | C1: City | D1: State | E1: Hub_Size | F1: Year | G1: Enplanements | H1: Total_Operating_Revenue | I1: Total_Aeronautical_Revenue | J1: Total_Commercial_Revenue | K1: Food_Beverage_Revenue | L1: Retail_Revenue | M1: Rental_Car_Revenue | N1: Parking_Ground_Revenue | O1: Land_Lease_Revenue | P1: Terminal_Service_Revenue | Q1: Hotel_Revenue | R1: Other_Commercial_Revenue | S1: Operating_Expenses | T1: Operating_Income | U1: Total_Capex | V1: Total_Debt | W1: Passenger_Aero_Revenue | X1: Data_Source | Y1: Source_URL | Z1: Verification_Status | AA1: Verification_Note
A2: ATL | B2: Hartsfield/Jackson Atlanta International | C2: Atlanta | D2: GA | E2: Large | F2: 2019 | G2: 54531948 | H2: 568507000 | K2: 55845000 | L2: 52259000 | M2: 43607000 | N2: 159640000 | P2: 12955000 | S2: 316189000 | T2: -5195000 | U2: 1077677000 | V2: 3148793000 | W2: 157871000 | X2: DWU transcription of FAA CATS Form 127 | Y2: https://dwuconsulting.com/airports/ATL | Z2: Pilot - verified subset | AA2: FAA CATS portal is under scheduled maintenance (Sep 23-30, 2026). Verified multi-year CATS fields populated; detailed Form 127 fields not visible in the indexed summary are intentionally left blank pending direct FAA export.
A3: ATL | B3: Hartsfield/Jackson Atlanta International | C3: Atlanta | D3: GA | E3: Large | F3: 2020 | G3: 39747596 | H3: 442318000 | K3: 42960000 | L3: 32688000 | M3: 32001000 | N3: 117313000 | P3: 12239000 | S3: 323202000 | T3: -153378000 | U3: 793389000 | V3: 3417948000 | W3: 132337000 | X3: DWU transcription of FAA CATS Form 127 | Y3: https://dwuconsulting.com/airports/ATL | Z3: Pilot - verified subset | AA3: FAA CATS portal is under scheduled maintenance (Sep 23-30, 2026). Verified multi-year CATS fields populated; detailed Form 127 fields not visible in the indexed summary are intentionally left blank pending direct FAA export.
A4: ATL | B4: Hartsfield/Jackson Atlanta International | C4: Atlanta | D4: GA | E4: Large | F4: 2021 | G4: 24928472 | H4: 354470000 | K4: 15375000 | L4: 9696000 | M4: 33423000 | N4: 71047000 | P4: 3468000 | S4: 318621000 | T4: -249958000 | U4: 741487000 | V4: 3366052000 | W4: 142332000 | X4: DWU transcription of FAA CATS Form 127 | Y4: https://dwuconsulting.com/airports/ATL | Z4: Pilot - verified subset | AA4: FAA CATS portal is under scheduled maintenance (Sep 23-30, 2026). Verified multi-year CATS fields populated; detailed Form 127 fields not visible in the indexed summary are intentionally left blank pending direct FAA export.
A5: ATL | B5: Hartsfield/Jackson Atlanta International | C5: Atlanta | D5: GA | E5: Large | F5: 2022 | G5: 44860920 | H5: 379356000 | K5: 17315000 | L5: 11485000 | M5: 45636000 | N5: 158141000 | P5: 4690000 | S5: 308864000 | T5: -221088000 | U5: 1081124000 | V5: 3809061000 | W5: 46714000 | X5: DWU transcription of FAA CATS Form 127 | Y5: https://dwuconsulting.com/airports/ATL | Z5: Pilot - verified subset | AA5: FAA CATS portal is under scheduled maintenance (Sep 23-30, 2026). Verified multi-year CATS fields populated; detailed Form 127 fields not visible in the indexed summary are intentionally left blank pending direct FAA export.
A6: ATL | B6: Hartsfield/Jackson Atlanta International | C6: Atlanta | D6: GA | E6: Large | F6: 2023 | G6: 49691940 | H6: 508301000 | K6: 33455000 | L6: 21847000 | M6: 53039000 | N6: 176694000 | P6: 6131000 | S6: 371155000 | T6: -167133000 | U6: 1081740000 | V6: 3471964000 | W6: 112705000 | X6: DWU transcription of FAA CATS Form 127 | Y6: https://dwuconsulting.com/airports/ATL | Z6: Pilot - verified subset | AA6: FAA CATS portal is under scheduled maintenance (Sep 23-30, 2026). Verified multi-year CATS fields populated; detailed Form 127 fields not visible in the indexed summary are intentionally left blank pending direct FAA export.
A7: ATL | B7: Hartsfield/Jackson Atlanta International | C7: Atlanta | D7: GA | E7: Large | F7: 2024 | G7: 53681363 | H7: 682121000 | K7: 65475000 | L7: 47319000 | M7: 54030000 | N7: 179454000 | P7: 14575000 | S7: 403204000 | T7: -40446000 | U7: 1593429000 | V7: 4407374000 | W7: 211157000 | X7: DWU transcription of FAA CATS Form 127 | Y7: https://dwuconsulting.com/airports/ATL | Z7: Pilot - verified subset | AA7: FAA CATS portal is under scheduled maintenance (Sep 23-30, 2026). Verified multi-year CATS fields populated; detailed Form 127 fields not visible in the indexed summary are intentionally left blank pending direct FAA export.
A8: DFW | B8: Dallas-Fort Worth International | C8: Fort Worth | D8: TX | E8: Large | F8: 2019 | G8: 36623417 | H8: 1023927000 | K8: 40135000 | L8: 24775000 | M8: 47480000 | N8: 184414000 | P8: 26888000 | S8: 571918000 | T8: 148812000 | U8: 407893000 | V8: 6272280000 | W8: 474389000 | X8: DWU transcription of FAA CATS Form 127 | Y8: https://dwuconsulting.com/airports/DFW | Z8: Pilot - verified subset | AA8: FAA CATS portal is under scheduled maintenance (Sep 23-30, 2026). Verified multi-year CATS fields populated; detailed Form 127 fields not visible in the indexed summary are intentionally left blank pending direct FAA export.
A9: DFW | B9: Dallas-Fort Worth International | C9: Fort Worth | D9: TX | E9: Large | F9: 2020 | G9: 23661724 | H9: 786181000 | K9: 25733000 | L9: 12071000 | M9: 32367000 | N9: 103714000 | P9: 22189000 | S9: 537558000 | T9: -61538000 | U9: 484581000 | V9: 6175800000 | W9: 432726000 | X9: DWU transcription of FAA CATS Form 127 | Y9: https://dwuconsulting.com/airports/DFW | Z9: Pilot - verified subset | AA9: FAA CATS portal is under scheduled maintenance (Sep 23-30, 2026). Verified multi-year CATS fields populated; detailed Form 127 fields not visible in the indexed summary are intentionally left blank pending direct FAA export.
A10: DFW | B10: Dallas-Fort Worth International | C10: Fort Worth | D10: TX | E10: Large | F10: 2021 | G10: 27633567 | H10: 791802000 | K10: 30979000 | L10: 12873000 | M10: 40503000 | N10: 116564000 | P10: 20929000 | S10: 511736000 | T10: 280066000 | U10: 642523000 | V10: 6321955000 | W10: 431828000 | X10: DWU transcription of FAA CATS Form 127 | Y10: https://dwuconsulting.com/airports/DFW | Z10: Pilot - verified subset | AA10: FAA CATS portal is under scheduled maintenance (Sep 23-30, 2026). Verified multi-year CATS fields populated; detailed Form 127 fields not visible in the indexed summary are intentionally left blank pending direct FAA export.
A11: DFW | B11: Dallas-Fort Worth International | C11: Fort Worth | D11: TX | E11: Large | F11: 2022 | G11: 36057362 | H11: 977955000 | K11: 27667000 | L11: 24176000 | M11: 52908000 | N11: 195997000 | P11: 33495000 | S11: 612684000 | T11: 30681000 | U11: 496883000 | V11: 7491495000 | W11: 439592000 | X11: DWU transcription of FAA CATS Form 127 | Y11: https://dwuconsulting.com/airports/DFW | Z11: Pilot - verified subset | AA11: FAA CATS portal is under scheduled maintenance (Sep 23-30, 2026). Verified multi-year CATS fields populated; detailed Form 127 fields not visible in the indexed summary are intentionally left blank pending direct FAA export.
A12: DFW | B12: Dallas-Fort Worth International | C12: Fort Worth | D12: TX | E12: Large | F12: 2023 | G12: 39755000 | H12: 1070890000 | K12: 54072000 | L12: 23073000 | M12: 58416000 | N12: 224105000 | P12: 36309000 | S12: 696079000 | T12: 18478000 | U12: 601365000 | V12: 7476675000 | W12: 459427000 | X12: DWU transcription of FAA CATS Form 127 | Y12: https://dwuconsulting.com/airports/DFW | Z12: Pilot - verified subset | AA12: FAA CATS portal is under scheduled maintenance (Sep 23-30, 2026). Verified multi-year CATS fields populated; detailed Form 127 fields not visible in the indexed summary are intentionally left blank pending direct FAA export.
A13: DFW | B13: Dallas-Fort Worth International | C13: Fort Worth | D13: TX | E13: Large | F13: 2024 | G13: 43370826 | H13: 1248691000 | K13: 61356000 | L13: 26017000 | M13: 64571000 | N13: 251054000 | P13: 38715000 | S13: 755329000 | T13: 119158000 | U13: 1064961000 | V13: 7948300000 | W13: 582834000 | X13: DWU transcription of FAA CATS Form 127 | Y13: https://dwuconsulting.com/airports/DFW | Z13: Pilot - verified subset | AA13: FAA CATS portal is under scheduled maintenance (Sep 23-30, 2026). Verified multi-year CATS fields populated; detailed Form 127 fields not visible in the indexed summary are intentionally left blank pending direct FAA export.
... A159: JFK | B159: John F Kennedy International | C159: New York | D159: NY | E159: Large | F159: 2020 | G159: 8329975 | H159: 920388000 | K159: 1676000 | L159: 9800000 | M159: 17147000 | N159: 36201000 | P159: 1806000 | S159: 816449000 | T159: -116729000 | U159: 234752000 | V159: 0 | W159: 553625000 | X159: DWU transcription of FAA CATS Form 127 | Y159: https://dwuconsulting.com/airports/JFK | Z159: Large-hub review - verified CATS subset | AA159: Airport-level CATS operating/commercial data are usable. Debt/credit metrics are system-linked and should not be benchmarked against stand-alone airports.
A160: JFK | B160: John F Kennedy International | C160: New York | D160: NY | E160: Large | F160: 2021 | G160: 15311865 | H160: 1087199000 | K160: 2634000 | L160: 11304000 | M160: 24858000 | N160: 80659000 | P160: 2987000 | S160: 722016000 | T160: 145646000 | U160: 128182000 | W160: 718440000 | X160: DWU transcription of FAA CATS Form 127 | Y160: https://dwuconsulting.com/airports/JFK | Z160: Large-hub review - verified CATS subset | AA160: Airport-level CATS operating/commercial data are usable. Debt/credit metrics are system-linked and should not be benchmarked against stand-alone airports.
A161: JFK | B161: John F Kennedy International | C161: New York | D161: NY | E161: Large | F161: 2022 | G161: 27459554 | H161: 1486589000 | K161: 10443000 | L161: 22210000 | M161: 34122000 | N161: 135362000 | P161: 3680000 | S161: 839989000 | T161: 425762000 | U161: 235006000 | W161: 897200000 | X161: DWU transcription of FAA CATS Form 127 | Y161: https://dwuconsulting.com/airports/JFK | Z161: Large-hub review - verified CATS subset | AA161: Airport-level CATS operating/commercial data are usable. Debt/credit metrics are system-linked and should not be benchmarked against stand-alone airports.
A162: JFK | B162: John F Kennedy International | C162: New York | D162: NY | E162: Large | F162: 2023 | G162: 31025194 | H162: 1679745000 | K162: 5992000 | L162: 32974000 | M162: 35315000 | N162: 151458000 | P162: 5231000 | S162: 944776000 | T162: 521580000 | U162: 558920000 | W162: 1044113000 | X162: DWU transcription of FAA CATS Form 127 | Y162: https://dwuconsulting.com/airports/JFK | Z162: Large-hub review - verified CATS subset | AA162: Airport-level CATS operating/commercial data are usable. Debt/credit metrics are system-linked and should not be benchmarked against stand-alone airports.
A163: JFK | B163: John F Kennedy International | C163: New York | D163: NY | E163: Large | F163: 2024 | G163: 31632992 | H163: 1898669000 | K163: 4954000 | L163: 35744000 | M163: 39060000 | N163: 140686000 | P163: 5192000 | S163: 1018209000 | T163: 676106000 | U163: 779180000 | W163: 1139224000 | X163: DWU transcription of FAA CATS Form 127 | Y163: https://dwuconsulting.com/airports/JFK | Z163: Large-hub review - verified CATS subset | AA163: Airport-level CATS operating/commercial data are usable. Debt/credit metrics are system-linked and should not be benchmarked against stand-alone airports.
A164: EWR | B164: Newark Liberty International | C164: Newark | D164: NJ | E164: Large | F164: 2019 | G164: 23168226 | H164: 1052070000 | K164: 6532000 | L164: 33853000 | M164: 41086000 | N164: 107437000 | P164: 1171000 | S164: 591802000 | T164: 311728000 | U164: 719703000 | W164: 634915000 | X164: DWU transcription of FAA CATS Form 127 | Y164: https://dwuconsulting.com/airports/EWR | Z164: Large-hub review - verified CATS subset | AA164: Airport-level CATS operating/commercial data are usable. Debt/credit metrics are reported at the PANYNJ system level.
A165: EWR | B165: Newark Liberty International | C165: Newark | D165: NJ | E165: Large | F165: 2020 | G165: 7973879 | H165: 739600000 | K165: 962000 | L165: 9224000 | M165: 17527000 | N165: 39875000 | P165: 689000 | S165: 544024000 | T165: 43945000 | U165: 690772000 | W165: 472747000 | X165: DWU transcription of FAA CATS Form 127 | Y165: https://dwuconsulting.com/airports/EWR | Z165: Large-hub review - verified CATS subset | AA165: Airport-level CATS operating/commercial data are usable. Debt/credit metrics are reported at the PANYNJ system level.
A166: EWR | B166: Newark Liberty International | C166: Newark | D166: NJ | E166: Large | F166: 2021 | G166: 14472936 | H166: 976598000 | K166: 4614000 | L166: 12009000 | M166: 28383000 | N166: 91758000 | P166: 1121000 | S166: 531396000 | T166: 289823000 | U166: 654193000 | W166: 634594000 | X166: DWU transcription of FAA CATS Form 127 | Y166: https://dwuconsulting.com/airports/EWR | Z166: Large-hub review - verified CATS subset | AA166: Airport-level CATS operating/commercial data are usable. Debt/credit metrics are reported at the PANYNJ system level.
A167: EWR | B167: Newark Liberty International | C167: Newark | D167: NJ | E167: Large | F167: 2022 | G167: 21796929 | H167: 1142687000 | K167: 6379000 | L167: 19635000 | M167: 44041000 | N167: 146273000 | P167: 1204000 | S167: 628688000 | T167: 340431000 | U167: 515522000 | W167: 637335000 | X167: DWU transcription of FAA CATS Form 127 | Y167: https://dwuconsulting.com/airports/EWR | Z167: Large-hub review - verified CATS subset | AA167: Airport-level CATS operating/commercial data are usable. Debt/credit metrics are reported at the PANYNJ system level.
A168: EWR | B168: Newark Liberty International | C168: Newark | D168: NJ | E168: Large | F168: 2023 | G168: 24556503 | H168: 1357187000 | K168: 22009000 | L168: 35905000 | M168: 51928000 | N168: 166997000 | P168: 1212000 | S168: 749584000 | T168: 367792000 | U168: 225818000 | W168: 751529000 | X168: DWU transcription of FAA CATS Form 127 | Y168: https://dwuconsulting.com/airports/EWR | Z168: Large-hub review - verified CATS subset | AA168: Airport-level CATS operating/commercial data are usable. Debt/credit metrics are reported at the PANYNJ system level.
A169: EWR | B169: Newark Liberty International | C169: Newark | D169: NJ | E169: Large | F169: 2024 | G169: 24426685 | H169: 1391598000 | K169: 24876000 | L169: 46193000 | M169: 57221000 | N169: 159208000 | P169: 1217000 | S169: 785968000 | T169: 364605000 | U169: 429118000 | W169: 773528000 | X169: DWU transcription of FAA CATS Form 127 | Y169: https://dwuconsulting.com/airports/EWR | Z169: Large-hub review - verified CATS subset | AA169: Airport-level CATS operating/commercial data are usable. Debt/credit metrics are reported at the PANYNJ system level.
A170: LGA | B170: La Guardia | C170: New York | D170: NY | E170: Large | F170: 2019 | G170: 15542447 | H170: 429046000 | K170: 1351000 | L170: 3005000 | M170: 15476000 | N170: 41928000 | P170: 234000 | S170: 370045000 | T170: -65008000 | U170: 732177000 | W170: 318825000 | X170: DWU transcription of FAA CATS Form 127 | Y170: https://dwuconsulting.com/airports/LGA | Z170: Large-hub review - verified CATS subset | AA170: Airport-level CATS operating/commercial data are usable. Debt/credit metrics are reported at the PANYNJ system level.
A171: LGA | B171: La Guardia | C171: New York | D171: NY | E171: Large | F171: 2020 | G171: 4184418 | H171: 326552000 | K171: 559000 | L171: 988000 | M171: 9386000 | N171: 23878000 | P171: 606000 | S171: 342727000 | T171: -184847000 | U171: 433558000 | W171: 259370000 | X171: DWU transcription of FAA CATS Form 127 | Y171: https://dwuconsulting.com/airports/LGA | Z171: Large-hub review - verified CATS subset | AA171: Airport-level CATS operating/commercial data are usable. Debt/credit metrics are reported at the PANYNJ system level.
... A175: LGA | B175: La Guardia | C175: New York | D175: NY | E175: Large | F175: 2024 | G175: 16771972 | H175: 579390000 | K175: 7327000 | L175: 3313000 | M175: 19271000 | N175: 94983000 | P175: 287000 | S175: 461223000 | T175: -104238000 | U175: 80847000 | W175: 389160000 | X175: DWU transcription of FAA CATS Form 127 | Y175: https://dwuconsulting.com/airports/LGA | Z175: Large-hub review - verified CATS subset | AA175: Airport-level CATS operating/commercial data are usable. Debt/credit metrics are reported at the PANYNJ system level.
A176: IAD | B176: Washington Dulles International | C176: Dulles | D176: VA | E176: Large | F176: 2019 | G176: 12326926 | H176: 458719000 | K176: 17170000 | L176: 23729000 | M176: 15777000 | N176: 89254000 | P176: 13800000 | S176: 248208000 | T176: 36710000 | U176: 38118000 | V176: 3084545000 | W176: 182652000 | X176: DWU transcription of FAA CATS Form 127 | Y176: https://dwuconsulting.com/airports/IAD | Z176: Large-hub review - verified CATS subset | AA176: Airport-level CATS operating/commercial data are usable. Bond/credit context is MWAA system-level; do not use debt metrics for peer ranking.
A177: IAD | B177: Washington Dulles International | C177: Dulles | D177: VA | E177: Large | F177: 2020 | G177: 4083437 | H177: 298447000 | K177: 5025000 | L177: 5875000 | M177: 7343000 | N177: 25394000 | P177: 7414000 | S177: 214139000 | T177: -88559000 | U177: 62327000 | V177: 3403451000 | W177: 153504000 | X177: DWU transcription of FAA CATS Form 127 | Y177: https://dwuconsulting.com/airports/IAD | Z177: Large-hub review - verified CATS subset | AA177: Airport-level CATS operating/commercial data are usable. Bond/credit context is MWAA system-level; do not use debt metrics for peer ranking.
A178: IAD | B178: Washington Dulles International | C178: Dulles | D178: VA | E178: Large | F178: 2021 | G178: 7385023 | H178: 317813000 | K178: 7074000 | L178: 5756000 | M178: 12464000 | N178: 47860000 | P178: 8093000 | S178: 215067000 | T178: -67360000 | U178: 167127000 | V178: 3451951000 | W178: 125587000 | X178: DWU transcription of FAA CATS Form 127 | Y178: https://dwuconsulting.com/airports/IAD | Z178: Large-hub review - verified CATS subset | AA178: Airport-level CATS operating/commercial data are usable. Bond/credit context is MWAA system-level; do not use debt metrics for peer ranking.
A179: IAD | B179: Washington Dulles International | C179: Dulles | D179: VA | E179: Large | F179: 2022 | G179: 10586011 | H179: 446818000 | K179: 9386000 | L179: 4807000 | M179: 17848000 | N179: 87747000 | P179: 10584000 | S179: 242055000 | T179: 32873000 | U179: 318307000 | V179: 3354221000 | W179: 187267000 | X179: DWU transcription of FAA CATS Form 127 | Y179: https://dwuconsulting.com/airports/IAD | Z179: Large-hub review - verified CATS subset | AA179: Airport-level CATS operating/commercial data are usable. Bond/credit context is MWAA system-level; do not use debt metrics for peer ranking.
A180: IAD | B180: Washington Dulles International | C180: Dulles | D180: VA | E180: Large | F180: 2023 | G180: 12385245 | H180: 515667000 | K180: 10793000 | L180: 12417000 | M180: 18763000 | N180: 111786000 | P180: 17116000 | S180: 259340000 | T180: 82322000 | U180: 100579000 | V180: 3398283000 | W180: 194548000 | X180: DWU transcription of FAA CATS Form 127 | Y180: https://dwuconsulting.com/airports/IAD | Z180: Large-hub review - verified CATS subset | AA180: Airport-level CATS operating/commercial data are usable. Bond/credit context is MWAA system-level; do not use debt metrics for peer ranking.
A181: IAD | B181: Washington Dulles International | C181: Dulles | D181: VA | E181: Large | F181: 2024 | G181: 13454238 | H181: 531826000 | K181: 21115000 | L181: 18163000 | M181: 19491000 | N181: 124692000 | P181: 18044000 | S181: 298305000 | T181: 62654000 | U181: 282519000 | V181: 3455469000 | W181: 173308000 | X181: DWU transcription of FAA CATS Form 127 | Y181: https://dwuconsulting.com/airports/IAD | Z181: Large-hub review - verified CATS subset | AA181: Airport-level CATS operating/commercial data are usable. Bond/credit context is MWAA system-level; do not use debt metrics for peer ranking.
A182: DCA | B182: Ronald Reagan Washington Ntl | C182: Arlington | D182: VA | E182: Large | F182: 2019 | G182: 11949040 | H182: 294890000 | K182: 18393000 | L182: 6016000 | M182: 17531000 | N182: 83276000 | P182: 9547000 | S182: 193136000 | T182: 52483000 | U182: 187041000 | V182: 1158295000 | W182: 137313000 | X182: DWU transcription of FAA CATS Form 127 | Y182: https://dwuconsulting.com/airports/DCA | Z182: Large-hub review - verified CATS subset | AA182: Airport-level CATS operating/commercial data are usable. Bond/credit context is MWAA system-level; do not use debt metrics for peer ranking.
A183: DCA | B183: Ronald Reagan Washington Ntl | C183: Arlington | D183: VA | E183: Large | F183: 2020 | G183: 3767537 | H183: 177685000 | K183: 5647000 | L183: 2044000 | M183: 6870000 | N183: 28936000 | P183: 5556000 | S183: 163594000 | T183: -38061000 | U183: 279088000 | V183: 1136262000 | W183: 107977000 | X183: DWU transcription of FAA CATS Form 127 | Y183: https://dwuconsulting.com/airports/DCA | Z183: Large-hub review - verified CATS subset | AA183: Airport-level CATS operating/commercial data are usable. Bond/credit context is MWAA system-level; do not use debt metrics for peer ranking.
A184: DCA | B184: Ronald Reagan Washington Ntl | C184: Arlington | D184: VA | E184: Large | F184: 2021 | G184: 7048963 | H184: 233919000 | K184: 7352000 | L184: 2684000 | M184: 16271000 | N184: 52546000 | P184: 7389000 | S184: 159719000 | T184: 6608000 | U184: 1270067000 | V184: 1409668000 | W184: 126862000 | X184: DWU transcription of FAA CATS Form 127 | Y184: https://dwuconsulting.com/airports/DCA | Z184: Large-hub review - verified CATS subset | AA184: Airport-level CATS operating/commercial data are usable. Bond/credit context is MWAA system-level; do not use debt metrics for peer ranking.
A185: DCA | B185: Ronald Reagan Washington Ntl | C185: Arlington | D185: VA | E185: Large | F185: 2022 | G185: 11969485 | H185: 303578000 | K185: 10619000 | L185: 3244000 | M185: 19476000 | N185: 95969000 | P185: 10544000 | S185: 188225000 | T185: 30962000 | U185: 58199000 | V185: 1258301000 | W185: 133293000 | X185: DWU transcription of FAA CATS Form 127 | Y185: https://dwuconsulting.com/airports/DCA | Z185: Large-hub review - verified CATS subset | AA185: Airport-level CATS operating/commercial data are usable. Bond/credit context is MWAA system-level; do not use debt metrics for peer ranking.
A186: DCA | B186: Ronald Reagan Washington Ntl | C186: Arlington | D186: VA | E186: Large | F186: 2023 | G186: 12735187 | H186: 318176000 | K186: 15323000 | L186: 4030000 | M186: 21820000 | N186: 106656000 | P186: 16144000 | S186: 196699000 | T186: 32858000 | U186: 126530000 | V186: 1258056000 | W186: 119456000 | X186: DWU transcription of FAA CATS Form 127 | Y186: https://dwuconsulting.com/airports/DCA | Z186: Large-hub review - verified CATS subset | AA186: Airport-level CATS operating/commercial data are usable. Bond/credit context is MWAA system-level; do not use debt metrics for peer ranking.
A187: DCA | B187: Ronald Reagan Washington Ntl | C187: Arlington | D187: VA | E187: Large | F187: 2024 | G187: 13113084 | H187: 316019000 | K187: 25511000 | L187: 4719000 | M187: 22890000 | N187: 110355000 | P187: 16112000 | S187: 225208000 | T187: 423000 | U187: 95547000 | V187: 1369652000 | W187: 101424000 | X187: DWU transcription of FAA CATS Form 127 | Y187: https://dwuconsulting.com/airports/DCA | Z187: Large-hub review - verified CATS subset | AA187: Airport-level CATS operating/commercial data are usable. Bond/credit context is MWAA system-level; do not use debt metrics for peer ranking.
... A199: MDW | B199: Chicago Midway International | C199: Chicago | D199: IL | E199: Large | F199: 2024 | G199: 10707000 | H199: 288948000 | K199: 14840000 | L199: 7802000 | M199: 10561000 | N199: 38467000 | P199: 76000 | S199: 197953000 | T199: 35131000 | U199: 18876000 | V199: 1412373000 | W199: 166924000 | X199: DWU transcription of FAA CATS Form 127 | Y199: https://dwuconsulting.com/airports/MDW | Z199: Large-hub review - verified CATS subset | AA199: Clean airport-level FAA CATS series; suitable for commercial and operating comparisons.

Sheet Data_Dictionary
A1: Column_Name | B1: FAA_Source_Field | C1: Purpose / Notes
A2: Airport_Code | B2: Location ID | C2: Primary airport identifier / join key
A3: Airport_Name | B3: Airport Name | C3: Airport display name
A4: City | B4: Airport metadata | C4: City used for labels and mapping
A5: State | B5: Airport metadata | C5: State used for mapping and filtering
A6: Hub_Size | B6: FAA hub classification | C6: Large / Medium hub peer benchmarking
A7: Year | B7: Reporting / fiscal year | C7: 2019–2024 project period
A8: Enplanements | B8: Form 127 Line 16.1 | C8: Fiscal-year passenger enplanements; denominator for per-passenger KPIs
A9: Total_Operating_Revenue | B9: Form 127 Line 5.0 | C9: Total airport operating revenue
A10: Total_Aeronautical_Revenue | B10: Form 127 Line 3.0 | C10: Total aeronautical revenue
A11: Total_Commercial_Revenue | B11: Form 127 Line 4.9 | C11: Total non-aeronautical / commercial revenue; major KPI
A12: Food_Beverage_Revenue | B12: Form 127 Line 4.2 | C12: Food and beverage concession revenue
... A23: Total_Debt | B23: Form 127 Line 11.4 | C23: Total debt

Sheet Project_Setup
A1: U.S. Airport Commercial Revenue & Passenger Monetization Analytics
A3: Item | B3: Value | C3: Notes | D3: Source
A4: Project Period | B4: 2019–2024 | C4: Use final full-year data
A5: Initial Scope | B5: All large + medium U.S. hub airports | C5: Final 25–30 airports selected after completeness checks
A6: Primary Source | B6: FAA Form 5100-127 | C6: Operating & Financial Summary | D6: https://cats.airports.faa.gov/reports/form_127/
A7: Primary KPI | B7: Commercial Revenue per Passenger | C7: Total Commercial Revenue / Fiscal-Year Enplanements
A8: Core Business Question | B8: How effectively are major U.S. airports converting passenger traffic into commercial revenue? | C8: Benchmark against comparable peers and diagnose revenue-stream gaps
A10: Airport Master | B10: Value | C10: Source Basis | D10: Source
A11: Large Hubs | B11: 31 | C11: Final CY2024 FAA classification | D11: https://www.faa.gov/airports/planning_capacity/passenger_allcargo_stats/passenger/arp-cy2024-commercial-service-enplanements.pdf
A12: Medium Hubs | B12: 32 | C12: Final CY2024 FAA classification | D12: https://www.faa.gov/airports/planning_capacity/passenger_allcargo_stats/passenger/arp-cy2024-commercial-service-enplanements.pdf
A13: Total Candidate Airports | B13: 63 | C13: Large + Medium hubs | D13: https://www.faa.gov/airports/planning_capacity/passenger_allcargo_stats/passenger/arp-cy2024-commercial-service-enplanements.pdf
A15: Pilot Extraction | B15: Value | C15: Status | D15: Notes
A16: Airports tested | B16: 5 | C16: Complete | D16: ATL, DFW, LAX, SEA, CLE
A17: Airport-years loaded | B17: 30 | C17: Complete | D17: 2019-2024 for each airport
A18: Detailed FAA line backfill | B18: 5 | C18: Pending | D18: Total aero/non-aero and land/hotel/other fields await direct FAA CATS export after maintenance.
A20: Data Quality Scoring | B20: Value | C20: Weight / Threshold | D20: Notes
A21: Core financial coverage | B21: 4 fields × 6 years | C21: 60% | D21: Enplanements, operating revenue, operating expenses, operating income
A22: Commercial detail coverage | B22: 5 fields × 6 years | C22: 40% | D22: Parking, rental car, food & beverage, retail, terminal service
A23: Excellent | B23: Current completeness | C23: >=90% | D23: Preferred for final shortlist
A24: Good / Review | B24: Current completeness | C24: 70–89% | D24: Inspect missingness before selection
A25: Pending FAA fields | B25: 5 fields × 6 years | C25: Not scored yet | D25: Tracked separately until direct FAA CATS export is available
A27: Working Set Expansion | B27: Value | C27: Status | D27: Notes
A28: Airports loaded | B28: 25 | C28: Complete | D28: 5 pilot + 20 additional airports
A29: Airport-year records | B29: 150 | C29: Complete | D29: 25 airports × 6 years (2019-2024)
A30: Current verified fields | B30: 14 | C30: Complete | D30: Core financial + commercial detail + passenger aeronautical revenue
A31: Pending FAA detail fields | B31: 5 | C31: Pending | D31: Total Aero, Total Commercial, Land Lease, Hotel, Other Commercial
A32: Remaining candidates | B32: 38 | C32: Reserve | D32: Only extract if final quality/comparability review requires replacements
A34: Large Hub Review | B34: Value | C34: Status | D34: Notes
A35: Missing large hubs reviewed | B35: 8 | C35: Complete | D35: CLT, JFK, EWR, LGA, IAD, DCA, HNL, MDW
A36: New airport-year rows | B36: 48 | C36: Complete | D36: 8 airports × 6 years
A37: Total loaded airports | B37: 33 | C37: Complete | D37: All 31 Large Hubs + CLE and DAL as Medium-Hub comparison candidates
A38: Pooled-authority airports | B38: 6 | C38: Flagged | D38: JFK, EWR, LGA, IAD, DCA, HNL
A39: Peer finance rule | B39: Commercial/operating yes | C39: Locked | D39: Do not rank pooled-authority airports on debt/credit metrics.
A41: Final Analysis Population | B41: Value | C41: Status | D41: Notes
A42: Final airports | B42: 31 | C42: Locked | D42: All FAA Large Hub airports
A43: Analysis period | B43: 2019–2024 | C43: Locked | D43: 6 fiscal years per airport
A44: Final airport-year rows | B44: 186 | C44: Locked | D44: 31 Large Hubs × 6 years
A45: Reserve airports | B45: 2 | C45: Retained | D45: CLE and DAL; Medium Hubs, QA / fallback only
A46: Debt/credit ranking | B46: Excluded | C46: Locked | D46: Not comparable for pooled-authority airports
A47: Primary analysis focus | B47: Commercial monetization | C47: Locked | D47: Passengers, operating revenue, commercial categories, expenses, operating income
...

Sheet Airport_Master
A1: Airport_Code | B1: Airport_Name | C1: City | D1: State | E1: Hub_Size | F1: FAA_Region_Code | G1: FAA_Region | H1: CY2024_Enplanements | I1: CY2023_Enplanements | J1: YoY_Change | K1: CY2024_Rank | L1: Source_URL
A2: ATL | B2: Hartsfield/Jackson Atlanta International | C2: Atlanta | D2: GA | E2: Large | F2: SO | G2: Southern | H2: 52511402 | I2: 50950068 | J2: 0.0306 | K2: 1 | L2: https://www.faa.gov/airports/planning_capacity/passenger_allcargo_stats/passenger/arp-cy2024-commercial-service-enplanements.pdf
A3: DFW | B3: Dallas-Fort Worth International | C3: Fort Worth | D3: TX | E3: Large | F3: SW | G3: Southwest | H3: 42351316 | I3: 39246212 | J3: 0.0791 | K3: 2 | L3: https://www.faa.gov/airports/planning_capacity/passenger_allcargo_stats/passenger/arp-cy2024-commercial-service-enplanements.pdf
A4: DEN | B4: Denver International | C4: Denver | D4: CO | E4: Large | F4: NM | G4: Northwest Mountain | H4: 40012895 | I4: 37863967 | J4: 0.0568 | K4: 3 | L4: https://www.faa.gov/airports/planning_capacity/passenger_allcargo_stats/passenger/arp-cy2024-commercial-service-enplanements.pdf
A5: ORD | B5: Chicago O'Hare International | C5: Chicago | D5: IL | E5: Large | F5: GL | G5: Great Lakes | H5: 38575693 | I5: 35843104 | J5: 0.0762 | K5: 4 | L5: https://www.faa.gov/airports/planning_capacity/passenger_allcargo_stats/passenger/arp-cy2024-commercial-service-enplanements.pdf
A6: LAX | B6: Los Angeles International | C6: Los Angeles | D6: CA | E6: Large | F6: WP | G6: Western-Pacific | H6: 37760834 | I6: 40956673 | J6: -0.078 | K6: 5 | L6: https://www.faa.gov/airports/planning_capacity/passenger_allcargo_stats/passenger/arp-cy2024-commercial-service-enplanements.pdf
A7: JFK | B7: John F Kennedy International | C7: New York | D7: NY | E7: Large | F7: EA | G7: Eastern | H7: 31466102 | I7: 30804355 | J7: 0.0215 | K7: 6 | L7: https://www.faa.gov/airports/planning_capacity/passenger_allcargo_stats/passenger/arp-cy2024-commercial-service-enplanements.pdf
A8: CLT | B8: Charlotte/Douglas International | C8: Charlotte | D8: NC | E8: Large | F8: SO | G8: Southern | H8: 28523822 | I8: 25896224 | J8: 0.1015 | K8: 7 | L8: https://www.faa.gov/airports/planning_capacity/passenger_allcargo_stats/passenger/arp-cy2024-commercial-service-enplanements.pdf
A9: LAS | B9: Harry Reid International | C9: Las Vegas | D9: NV | E9: Large | F9: WP | G9: Western-Pacific | H9: 28244966 | I9: 27896199 | J9: 0.0125 | K9: 8 | L9: https://www.faa.gov/airports/planning_capacity/passenger_allcargo_stats/passenger/arp-cy2024-commercial-service-enplanements.pdf
A10: MCO | B10: Orlando International | C10: Orlando | D10: FL | E10: Large | F10: SO | G10: Southern | H10: 27859783 | I10: 28033205 | J10: -0.0062 | K10: 9 | L10: https://www.faa.gov/airports/planning_capacity/passenger_allcargo_stats/passenger/arp-cy2024-commercial-service-enplanements.pdf
A11: MIA | B11: Miami International | C11: Miami | D11: FL | E11: Large | F11: SO | G11: Southern | H11: 26588002 | I11: 24717048 | J11: 0.0757 | K11: 10 | L11: https://www.faa.gov/airports/planning_capacity/passenger_allcargo_stats/passenger/arp-cy2024-commercial-service-enplanements.pdf
A12: PHX | B12: Phoenix Sky Harbor International | C12: Phoenix | D12: AZ | E12: Large | F12: WP | G12: Western-Pacific | H12: 25595723 | I12: 23880504 | J12: 0.0718 | K12: 11 | L12: https://www.faa.gov/airports/planning_capacity/passenger_allcargo_stats/passenger/arp-cy2024-commercial-service-enplanements.pdf
A13: SEA | B13: Seattle-Tacoma International | C13: Seattle | D13: WA | E13: Large | F13: NM | G13: Northwest Mountain | H13: 25414592 | I13: 24594210 | J13: 0.0334 | K13: 12 | L13: https://www.faa.gov/airports/planning_capacity/passenger_allcargo_stats/passenger/arp-cy2024-commercial-service-enplanements.pdf
... A64: BOI | B64: Boise Air Trml/Gowen Field | C64: Boise | D64: ID | E64: Medium | F64: NM | G64: Northwest Mountain | H64: 2475370 | I64: 2369164 | J64: 0.0448 | K64: 63 | L64: https://www.faa.gov/airports/planning_capacity/passenger_allcargo_stats/passenger/arp-cy2024-commercial-service-enplanements.pdf

Sheet Pilot_Validation
A1: Airport_Code | B1: Airport_Name | C1: Hub_Size | D1: Years_Loaded | E1: Enplanements | F1: Total_Operating_Revenue | G1: Operating_Expenses | H1: Operating_Income | I1: Parking | J1: Rental_Car | K1: Food_Beverage | L1: Retail | M1: Terminal_Service | N1: Passenger_Aero | O1: Total_Aero | P1: Total_Commercial | Q1: Land_Lease | R1: Hotel | S1: Other_Commercial | T1: Pilot_Result | U1: Next_Action
A2: ATL | B2: Hartsfield/Jackson Atlanta International | C2: Large | D2: 2019-2024 | E2: Complete | F2: Complete | G2: Complete | H2: Complete | I2: Complete | J2: Complete | K2: Complete | L2: Complete | M2: Complete | N2: Complete | O2: Pending direct FAA | P2: Pending direct FAA | Q2: Pending direct FAA | R2: Pending direct FAA | S2: Pending direct FAA | T2: PASS - core trend fields verified | U2: Backfill detailed Form 127 revenue lines after FAA CATS maintenance; then run full 63-airport completeness test.
A3: DFW | B3: Dallas-Fort Worth International | C3: Large | D3: 2019-2024 | E3: Complete | F3: Complete | G3: Complete | H3: Complete | I3: Complete | J3: Complete | K3: Complete | L3: Complete | M3: Complete | N3: Complete | O3: Pending direct FAA | P3: Pending direct FAA | Q3: Pending direct FAA | R3: Pending direct FAA | S3: Pending direct FAA | T3: PASS - core trend fields verified | U3: Backfill detailed Form 127 revenue lines after FAA CATS maintenance; then run full 63-airport completeness test.
A4: LAX | B4: Los Angeles International | C4: Large | D4: 2019-2024 | E4: Complete | F4: Complete | G4: Complete | H4: Complete | I4: Complete | J4: Complete | K4: Complete | L4: Complete | M4: Complete | N4: Complete | O4: Pending direct FAA | P4: Pending direct FAA | Q4: Pending direct FAA | R4: Pending direct FAA | S4: Pending direct FAA | T4: PASS - core trend fields verified | U4: Backfill detailed Form 127 revenue lines after FAA CATS maintenance; then run full 63-airport completeness test.
A5: SEA | B5: Seattle-Tacoma International | C5: Large | D5: 2019-2024 | E5: Complete | F5: Complete | G5: Complete | H5: Complete | I5: Complete | J5: Complete | K5: Complete | L5: Complete | M5: Complete | N5: Complete | O5: Pending direct FAA | P5: Pending direct FAA | Q5: Pending direct FAA | R5: Pending direct FAA | S5: Pending direct FAA | T5: PASS - core trend fields verified | U5: Backfill detailed Form 127 revenue lines after FAA CATS maintenance; then run full 63-airport completeness test.
A6: CLE | B6: Cleveland-Hopkins International | C6: Medium | D6: 2019-2024 | E6: Complete | F6: Complete | G6: Complete | H6: Complete | I6: Complete | J6: Complete | K6: Complete | L6: Complete | M6: Complete | N6: Complete | O6: Pending direct FAA | P6: Pending direct FAA | Q6: Pending direct FAA | R6: Pending direct FAA | S6: Pending direct FAA | T6: PASS - core trend fields verified | U6: Backfill detailed Form 127 revenue lines after FAA CATS maintenance; then run full 63-airport completeness test.

Sheet Data_Quality
A1: Airport Data Quality & Completeness Scorecard
A2: Purpose: select airports with reliable 2019–2024 data. Zeros count as reported values; blanks count as missing. Pending FAA Form 127 fields are tracked separately and do not reduce the current completeness score.
A4: Candidate Airports | B4: Loaded Airports | C4: 6-Year Coverage | D4: Excellent (>=90%) | E4: Good (80-89%) | F4: Review (70-79%) | G4: Exclude (<70%) | H4: FAA Backfill Pending | J4: Scoring Component | K4: Fields | L4: Weight | M4: Rule | N4: Interpretation
A5: =COUNTA(Airport_Master!$A$2:$A$64) -> 63 | B5: =COUNTIF($D$9:$D$71,">0") -> 33 | C5: =COUNTIF($D$9:$D$71,6) -> 33 | D5: =COUNTIF($R$9:$R$71,">=0.9") -> 33 | E5: =COUNTIFS($R$9:$R$71,">=0.8",$R$9:$R$71,"<0.9") -> 0 | F5: =COUNTIFS($R$9:$R$71,">=0.7",$R$9:$R$71,"<0.8") -> 0 | G5: =COUNTIFS($D$9:$D$71,">0",$R$9:$R$71,"<0.7") -> 0 | H5: =COUNTIFS($D$9:$D$71,">0",$S$9:$S$71,"<1") -> 33 | J5: Core financial coverage | K5: Enplanements, Operating Revenue, Operating Expenses, Operating Income | L5: 0.6 | M5: Nonblank years / 24 expected cells | N5: Required for reliable trend and financial analysis
J6: Commercial detail coverage | K6: Parking, Rental Car, Food & Beverage, Retail, Terminal Service | L6: 0.4 | M6: Nonblank years / 30 expected cells | N6: Required for passenger-monetization diagnosis
J7: Pending FAA backfill | K7: Total Aero, Total Commercial, Land Lease, Hotel, Other Commercial | M7: Tracked separately; not scored yet | N7: Will be added after direct FAA CATS export is available
A8: Airport_Code | B8: Airport_Name | C8: Hub_Size | D8: Years_Loaded | E8: Year_Coverage_% | F8: Enplanements_Yrs | G8: Operating_Revenue_Yrs | H8: Operating_Expenses_Yrs | I8: Operating_Income_Yrs | J8: Parking_Yrs | K8: Rental_Car_Yrs | L8: Food_Beverage_Yrs | M8: Retail_Yrs | N8: Terminal_Service_Yrs | O8: Core_Coverage_% | P8: Commercial_Detail_% | Q8: Zero_Value_Flag_Count | R8: Current_Completeness_% | S8: Pending_FAA_Coverage_% | T8: Selection_Status
A9: =Airport_Master!A2 -> ATL | B9: =Airport_Master!B2 -> Hartsfield/Jackson Atlanta International | C9: =Airport_Master!E2 -> Large | D9: =COUNTIFS(Form127_Raw!$A$2:$A$1000,$A9,Form127_Raw!$F$2:$F$1000,">=2019",Form127_Raw!$F$2:$F$1000,"<=2024") -> 6 | E9: =D9/6 -> 1 | F9: =COUNTIFS(Form127_Raw!$A$2:$A$1000,$A9,Form127_Raw!$F$2:$F$1000,">=2019",Form127_Raw!$F$2:$F$1000,"<=2024",Form127_Raw!$G$2:$G$1000,"<>") -> 6 | G9: =COUNTIFS(Form127_Raw!$A$2:$A$1000,$A9,Form127_Raw!$F$2:$F$1000,">=2019",Form127_Raw!$F$2:$F$1000,"<=2024",Form127_Raw!$H$2:$H$1000,"<>") -> 6 | H9: =COUNTIFS(Form127_Raw!$A$2:$A$1000,$A9,Form127_Raw!$F$2:$F$1000,">=2019",Form127_Raw!$F$2:$F$1000,"<=2024",Form127_Raw!$S$2:$S$1000,"<>") -> 6 | I9: =COUNTIFS(Form127_Raw!$A$2:$A$1000,$A9,Form127_Raw!$F$2:$F$1000,">=2019",Form127_Raw!$F$2:$F$1000,"<=2024",Form127_Raw!$T$2:$T$1000,"<>") -> 6 | J9: =COUNTIFS(Form127_Raw!$A$2:$A$1000,$A9,Form127_Raw!$F$2:$F$1000,">=2019",Form127_Raw!$F$2:$F$1000,"<=2024",Form127_Raw!$N$2:$N$1000,"<>") -> 6 | K9: =COUNTIFS(Form127_Raw!$A$2:$A$1000,$A9,Form127_Raw!$F$2:$F$1000,">=2019",Form127_Raw!$F$2:$F$1000,"<=2024",Form127_Raw!$M$2:$M$1000,"<>") -> 6 | L9: =COUNTIFS(Form127_Raw!$A$2:$A$1000,$A9,Form127_Raw!$F$2:$F$1000,">=2019",Form127_Raw!$F$2:$F$1000,"<=2024",Form127_Raw!$K$2:$K$1000,"<>") -> 6 | M9: =COUNTIFS(Form127_Raw!$A$2:$A$1000,$A9,Form127_Raw!$F$2:$F$1000,">=2019",Form127_Raw!$F$2:$F$1000,"<=2024",Form127_Raw!$L$2:$L$1000,"<>") -> 6 | N9: =COUNTIFS(Form127_Raw!$A$2:$A$1000,$A9,Form127_Raw!$F$2:$F$1000,">=2019",Form127_Raw!$F$2:$F$1000,"<=2024",Form127_Raw!$P$2:$P$1000,"<>") -> 6 | O9: =SUM(F9:I9)/24 -> 1 | P9: =SUM(J9:N9)/30 -> 1 | Q9: =COUNTIFS(Form127_Raw!$A$2:$A$1000,$A9,Form127_Raw!$F$2:$F$1000,">=2019",Form127_Raw!$F$2:$F$1000,"<=2024",Form127_Raw!$N$2:$N$1000,0)+COUNTIFS(Form127_Raw!$A$2:$A$1000,$A9,Form127_Raw!$F$2:$F$1000,">=2019",Form127_Raw!$F$2:$F$1000,"<=2024",Form127_Raw!$M$2:$M$1000,0)+COUNTIFS(Form127_Raw!$A$2:$A$1000,$A9,Form127_Raw!$F$2:$F$1000,">=2019",Form127_Raw!$F$2:$F$1000,"<=2024",Form127_Raw!$K$2:$K$1000,0)+COUNTIFS(Form127_Raw!$A$2:$A$1000,$A9,Form127_Raw!$F$2:$F$1000,">=2019",Form127_Raw!$F$2:$F$1000,"<=2024",Form127_Raw!$L$2:$L$1000,0)+COUNTIFS(Form127_Raw!$A$2:$A$1000,$A9,Form127_Raw!$F$2:$F$1000,">=2019",Form127_Raw!$F$2:$F$1000,"<=2024",Form127_Raw!$P$2:$P$1000,0) -> 0 | R9: =O9*0.6+P9*0.4 -> 1 | S9: =(COUNTIFS(Form127_Raw!$A$2:$A$1000,$A9,Form127_Raw!$F$2:$F$1000,">=2019",Form127_Raw!$F$2:$F$1000,"<=2024",Form127_Raw!$I$2:$I$1000,"<>")+COUNTIFS(Form127_Raw!$A$2:$A$1000,$A9,Form127_Raw!$F$2:$F$1000,">=2019",Form127_Raw!$F$2:$F$1000,"<=2024",Form127_Raw!$J$2:$J$1000,"<>")+COUNTIFS(Form127_Raw!$A$2:$A$1000,$A9,Form127_Raw!$F$2:$F$1000,">=2019",Form127_Raw!$F$2:$F$1000,"<=2024",Form127_Raw!$O$2:$O$1000,"<>")+COUNTIFS(Form127_Raw!$A$2:$A$1000,$A9,Form127_Raw!$F$2:$F$1000,">=2019",Form127_Raw!$F$2:$F$1000,"<=2024",Form127_Raw!$Q$2:$Q$1000,"<>")+COUNTIFS(Form127_Raw!$A$2:$A$1000,$A9,Form127_Raw!$F$2:$F$1000,">=2019",Form127_Raw!$F$2:$F$1000,"<=2024",Form127_Raw!$R$2:$R$1000,"<>"))/30 -> 0 | T9: =IF(D9=0,"Not Loaded",IF(R9>=0.9,IF(S9=1,"Ready for Final Selection","Excellent - FAA Backfill Pending"),IF(R9>=0.8,"Good - Review Missing Fields",IF(R9>=0.7,"Manual Review","Exclude / Incomplete")))) -> Excellent - FAA Backfill Pending
A10: =Airport_Master!A3 -> DFW | B10: =Airport_Master!B3 -> Dallas-Fort Worth International | C10: =Airport_Master!E3 -> Large | D10: =COUNTIFS(Form127_Raw!$A$2:$A$1000,$A10,Form127_Raw!$F$2:$F$1000,">=2019",Form127_Raw!$F$2:$F$1000,"<=2024") -> 6 | E10: =D10/6 -> 1 | F10: =COUNTIFS(Form127_Raw!$A$2:$A$1000,$A10,Form127_Raw!$F$2:$F$1000,">=2019",Form127_Raw!$F$2:$F$1000,"<=2024",Form127_Raw!$G$2:$G$1000,"<>") -> 6 | G10: =COUNTIFS(Form127_Raw!$A$2:$A$1000,$A10,Form127_Raw!$F$2:$F$1000,">=2019",Form127_Raw!$F$2:$F$1000,"<=2024",Form127_Raw!$H$2:$H$1000,"<>") -> 6 | H10: =COUNTIFS(Form127_Raw!$A$2:$A$1000,$A10,Form127_Raw!$F$2:$F$1000,">=2019",Form127_Raw!$F$2:$F$1000,"<=2024",Form127_Raw!$S$2:$S$1000,"<>") -> 6 | I10: =COUNTIFS(Form127_Raw!$A$2:$A$1000,$A10,Form127_Raw!$F$2:$F$1000,">=2019",Form127_Raw!$F$2:$F$1000,"<=2024",Form127_Raw!$T$2:$T$1000,"<>") -> 6 | J10: =COUNTIFS(Form127_Raw!$A$2:$A$1000,$A10,Form127_Raw!$F$2:$F$1000,">=2019",Form127_Raw!$F$2:$F$1000,"<=2024",Form127_Raw!$N$2:$N$1000,"<>") -> 6 | K10: =COUNTIFS(Form127_Raw!$A$2:$A$1000,$A10,Form127_Raw!$F$2:$F$1000,">=2019",Form127_Raw!$F$2:$F$1000,"<=2024",Form127_Raw!$M$2:$M$1000,"<>") -> 6 | L10: =COUNTIFS(Form127_Raw!$A$2:$A$1000,$A10,Form127_Raw!$F$2:$F$1000,">=2019",Form127_Raw!$F$2:$F$1000,"<=2024",Form127_Raw!$K$2:$K$1000,"<>") -> 6 | M10: =COUNTIFS(Form127_Raw!$A$2:$A$1000,$A10,Form127_Raw!$F$2:$F$1000,">=2019",Form127_Raw!$F$2:$F$1000,"<=2024",Form127_Raw!$L$2:$L$1000,"<>") -> 6 | N10: =COUNTIFS(Form127_Raw!$A$2:$A$1000,$A10,Form127_Raw!$F$2:$F$1000,">=2019",Form127_Raw!$F$2:$F$1000,"<=2024",Form127_Raw!$P$2:$P$1000,"<>") -> 6 | O10: =SUM(F10:I10)/24 -> 1 | P10: =SUM(J10:N10)/30 -> 1 | Q10: =COUNTIFS(Form127_Raw!$A$2:$A$1000,$A10,Form127_Raw!$F$2:$F$1000,">=2019",Form127_Raw!$F$2:$F$1000,"<=2024",Form127_Raw!$N$2:$N$1000,0)+COUNTIFS(Form127_Raw!$A$2:$A$1000,$A10,Form127_Raw!$F$2:$F$1000,">=2019",Form127_Raw!$F$2:$F$1000,"<=2024",Form127_Raw!$M$2:$M$1000,0)+COUNTIFS(Form127_Raw!$A$2:$A$1000,$A10,Form127_Raw!$F$2:$F$1000,">=2019",Form127_Raw!$F$2:$F$1000,"<=2024",Form127_Raw!$K$2:$K$1000,0)+COUNTIFS(Form127_Raw!$A$2:$A$1000,$A10,Form127_Raw!$F$2:$F$1000,">=2019",Form127_Raw!$F$2:$F$1000,"<=2024",Form127_Raw!$L$2:$L$1000,0)+COUNTIFS(Form127_Raw!$A$2:$A$1000,$A10,Form127_Raw!$F$2:$F$1000,">=2019",Form127_Raw!$F$2:$F$1000,"<=2024",Form127_Raw!$P$2:$P$1000,0) -> 0 | R10: =O10*0.6+P10*0.4 -> 1 | S10: =(COUNTIFS(Form127_Raw!$A$2:$A$1000,$A10,Form127_Raw!$F$2:$F$1000,">=2019",Form127_Raw!$F$2:$F$1000,"<=2024",Form127_Raw!$I$2:$I$1000,"<>")+COUNTIFS(Form127_Raw!$A$2:$A$1000,$A10,Form127_Raw!$F$2:$F$1000,">=2019",Form127_Raw!$F$2:$F$1000,"<=2024",Form127_Raw!$J$2:$J$1000,"<>")+COUNTIFS(Form127_Raw!$A$2:$A$1000,$A10,Form127_Raw!$F$2:$F$1000,">=2019",Form127_Raw!$F$2:$F$1000,"<=2024",Form127_Raw!$O$2:$O$1000,"<>")+COUNTIFS(Form127_Raw!$A$2:$A$1000,$A10,Form127_Raw!$F$2:$F$1000,">=2019",Form127_Raw!$F$2:$F$1000,"<=2024",Form127_Raw!$Q$2:$Q$1000,"<>")+COUNTIFS(Form127_Raw!$A$2:$A$1000,$A10,Form127_Raw!$F$2:$F$1000,">=2019",Form127_Raw!$F$2:$F$1000,"<=2024",Form127_Raw!$R$2:$R$1000,"<>"))/30 -> 0 | T10: =IF(D10=0,"Not Loaded",IF(R10>=0.9,IF(S10=1,"Ready for Final Selection","Excellent - FAA Backfill Pending"),IF(R10>=0.8,"Good - Review Missing Fields",IF(R10>=0.7,"Manual Review","Exclude / Incomplete")))) -> Excellent - FAA Backfill Pending
A11: =Airport_Master!A4 -> DEN | B11: =Airport_Master!B4 -> Denver International | C11: =Airport_Master!E4 -> Large | D11: =COUNTIFS(Form127_Raw!$A$2:$A$1000,$A11,Form127_Raw!$F$2:$F$1000,">=2019",Form127_Raw!$F$2:$F$1000,"<=2024") -> 6 | E11: =D11/6 -> 1 | F11: =COUNTIFS(Form127_Raw!$A$2:$A$1000,$A11,Form127_Raw!$F$2:$F$1000,">=2019",Form127_Raw!$F$2:$F$1000,"<=2024",Form127_Raw!$G$2:$G$1000,"<>") -> 6 | G11: =COUNTIFS(Form127_Raw!$A$2:$A$1000,$A11,Form127_Raw!$F$2:$F$1000,">=2019",Form127_Raw!$F$2:$F$1000,"<=2024",Form127_Raw!$H$2:$H$1000,"<>") -> 6 | H11: =COUNTIFS(Form127_Raw!$A$2:$A$1000,$A11,Form127_Raw!$F$2:$F$1000,">=2019",Form127_Raw!$F$2:$F$1000,"<=2024",Form127_Raw!$S$2:$S$1000,"<>") -> 6 | I11: =COUNTIFS(Form127_Raw!$A$2:$A$1000,$A11,Form127_Raw!$F$2:$F$1000,">=2019",Form127_Raw!$F$2:$F$1000,"<=2024",Form127_Raw!$T$2:$T$1000,"<>") -> 6 | J11: =COUNTIFS(Form127_Raw!$A$2:$A$1000,$A11,Form127_Raw!$F$2:$F$1000,">=2019",Form127_Raw!$F$2:$F$1000,"<=2024",Form127_Raw!$N$2:$N$1000,"<>") -> 6 | K11: =COUNTIFS(Form127_Raw!$A$2:$A$1000,$A11,Form127_Raw!$F$2:$F$1000,">=2019",Form127_Raw!$F$2:$F$1000,"<=2024",Form127_Raw!$M$2:$M$1000,"<>") -> 6 | L11: =COUNTIFS(Form127_Raw!$A$2:$A$1000,$A11,Form127_Raw!$F$2:$F$1000,">=2019",Form127_Raw!$F$2:$F$1000,"<=2024",Form127_Raw!$K$2:$K$1000,"<>") -> 6 | M11: =COUNTIFS(Form127_Raw!$A$2:$A$1000,$A11,Form127_Raw!$F$2:$F$1000,">=2019",Form127_Raw!$F$2:$F$1000,"<=2024",Form127_Raw!$L$2:$L$1000,"<>") -> 6 | N11: =COUNTIFS(Form127_Raw!$A$2:$A$1000,$A11,Form127_Raw!$F$2:$F$1000,">=2019",Form127_Raw!$F$2:$F$1000,"<=2024",Form127_Raw!$P$2:$P$1000,"<>") -> 6 | O11: =SUM(F11:I11)/24 -> 1 | P11: =SUM(J11:N11)/30 -> 1 | Q11: =COUNTIFS(Form127_Raw!$A$2:$A$1000,$A11,Form127_Raw!$F$2:$F$1000,">=2019",Form127_Raw!$F$2:$F$1000,"<=2024",Form127_Raw!$N$2:$N$1000,0)+COUNTIFS(Form127_Raw!$A$2:$A$1000,$A11,Form127_Raw!$F$2:$F$1000,">=2019",Form127_Raw!$F$2:$F$1000,"<=2024",Form127_Raw!$M$2:$M$1000,0)+COUNTIFS(Form127_Raw!$A$2:$A$1000,$A11,Form127_Raw!$F$2:$F$1000,">=2019",Form127_Raw!$F$2:$F$1000,"<=2024",Form127_Raw!$K$2:$K$1000,0)+COUNTIFS(Form127_Raw!$A$2:$A$1000,$A11,Form127_Raw!$F$2:$F$1000,">=2019",Form127_Raw!$F$2:$F$1000,"<=2024",Form127_Raw!$L$2:$L$1000,0)+COUNTIFS(Form127_Raw!$A$2:$A$1000,$A11,Form127_Raw!$F$2:$F$1000,">=2019",Form127_Raw!$F$2:$F$1000,"<=2024",Form127_Raw!$P$2:$P$1000,0) -> 0 | R11: =O11*0.6+P11*0.4 -> 1 | S11: =(COUNTIFS(Form127_Raw!$A$2:$A$1000,$A11,Form127_Raw!$F$2:$F$1000,">=2019",Form127_Raw!$F$2:$F$1000,"<=2024",Form127_Raw!$I$2:$I$1000,"<>")+COUNTIFS(Form127_Raw!$A$2:$A$1000,$A11,Form127_Raw!$F$2:$F$1000,">=2019",Form127_Raw!$F$2:$F$1000,"<=2024",Form127_Raw!$J$2:$J$1000,"<>")+COUNTIFS(Form127_Raw!$A$2:$A$1000,$A11,Form127_Raw!$F$2:$F$1000,">=2019",Form127_Raw!$F$2:$F$1000,"<=2024",Form127_Raw!$O$2:$O$1000,"<>")+COUNTIFS(Form127_Raw!$A$2:$A$1000,$A11,Form127_Raw!$F$2:$F$1000,">=2019",Form127_Raw!$F$2:$F$1000,"<=2024",Form127_Raw!$Q$2:$Q$1000,"<>")+COUNTIFS(Form127_Raw!$A$2:$A$1000,$A11,Form127_Raw!$F$2:$F$1000,">=2019",Form127_Raw!$F$2:$F$1000,"<=2024",Form127_Raw!$R$2:$R$1000,"<>"))/30 -> 0 | T11: =IF(D11=0,"Not Loaded",IF(R11>=0.9,IF(S11=1,"Ready for Final Selection","Excellent - FAA Backfill Pending"),IF(R11>=0.8,"Good - Review Missing Fields",IF(R11>=0.7,"Manual Review","Exclude / Incomplete")))) -> Excellent - FAA Backfill Pending
A12: =Airport_Master!A5 -> ORD | B12: =Airport_Master!B5 -> Chicago O'Hare International | C12: =Airport_Master!E5 -> Large | D12: =COUNTIFS(Form127_Raw!$A$2:$A$1000,$A12,Form127_Raw!$F$2:$F$1000,">=2019",Form127_Raw!$F$2:$F$1000,"<=2024") -> 6 | E12: =D12/6 -> 1 | F12: =COUNTIFS(Form127_Raw!$A$2:$A$1000,$A12,Form127_Raw!$F$2:$F$1000,">=2019",Form127_Raw!$F$2:$F$1000,"<=2024",Form127_Raw!$G$2:$G$1000,"<>") -> 6 | G12: =COUNTIFS(Form127_Raw!$A$2:$A$1000,$A12,Form127_Raw!$F$2:$F$1000,">=2019",Form127_Raw!$F$2:$F$1000,"<=2024",Form127_Raw!$H$2:$H$1000,"<>") -> 6 | H12: =COUNTIFS(Form127_Raw!$A$2:$A$1000,$A12,Form127_Raw!$F$2:$F$1000,">=2019",Form127_Raw!$F$2:$F$1000,"<=2024",Form127_Raw!$S$2:$S$1000,"<>") -> 6 | I12: =COUNTIFS(Form127_Raw!$A$2:$A$1000,$A12,Form127_Raw!$F$2:$F$1000,">=2019",Form127_Raw!$F$2:$F$1000,"<=2024",Form127_Raw!$T$2:$T$1000,"<>") -> 6 | J12: =COUNTIFS(Form127_Raw!$A$2:$A$1000,$A12,Form127_Raw!$F$2:$F$1000,">=2019",Form127_Raw!$F$2:$F$1000,"<=2024",Form127_Raw!$N$2:$N$1000,"<>") -> 6 | K12: =COUNTIFS(Form127_Raw!$A$2:$A$1000,$A12,Form127_Raw!$F$2:$F$1000,">=2019",Form127_Raw!$F$2:$F$1000,"<=2024",Form127_Raw!$M$2:$M$1000,"<>") -> 6 | L12: =COUNTIFS(Form127_Raw!$A$2:$A$1000,$A12,Form127_Raw!$F$2:$F$1000,">=2019",Form127_Raw!$F$2:$F$1000,"<=2024",Form127_Raw!$K$2:$K$1000,"<>") -> 6 | M12: =COUNTIFS(Form127_Raw!$A$2:$A$1000,$A12,Form127_Raw!$F$2:$F$1000,">=2019",Form127_Raw!$F$2:$F$1000,"<=2024",Form127_Raw!$L$2:$L$1000,"<>") -> 6 | N12: =COUNTIFS(Form127_Raw!$A$2:$A$1000,$A12,Form127_Raw!$F$2:$F$1000,">=2019",Form127_Raw!$F$2:$F$1000,"<=2024",Form127_Raw!$P$2:$P$1000,"<>") -> 6 | O12: =SUM(F12:I12)/24 -> 1 | P12: =SUM(J12:N12)/30 -> 1 | Q12: =COUNTIFS(Form127_Raw!$A$2:$A$1000,$A12,Form127_Raw!$F$2:$F$1000,">=2019",Form127_Raw!$F$2:$F$1000,"<=2024",Form127_Raw!$N$2:$N$1000,0)+COUNTIFS(Form127_Raw!$A$2:$A$1000,$A12,Form127_Raw!$F$2:$F$1000,">=2019",Form127_Raw!$F$2:$F$1000,"<=2024",Form127_Raw!$M$2:$M$1000,0)+COUNTIFS(Form127_Raw!$A$2:$A$1000,$A12,Form127_Raw!$F$2:$F$1000,">=2019",Form127_Raw!$F$2:$F$1000,"<=2024",Form127_Raw!$K$2:$K$1000,0)+COUNTIFS(Form127_Raw!$A$2:$A$1000,$A12,Form127_Raw!$F$2:$F$1000,">=2019",Form127_Raw!$F$2:$F$1000,"<=2024",Form127_Raw!$L$2:$L$1000,0)+COUNTIFS(Form127_Raw!$A$2:$A$1000,$A12,Form127_Raw!$F$2:$F$1000,">=2019",Form127_Raw!$F$2:$F$1000,"<=2024",Form127_Raw!$P$2:$P$1000,0) -> 0 | R12: =O12*0.6+P12*0.4 -> 1 | S12: =(COUNTIFS(Form127_Raw!$A$2:$A$1000,$A12,Form127_Raw!$F$2:$F$1000,">=2019",Form127_Raw!$F$2:$F$1000,"<=2024",Form127_Raw!$I$2:$I$1000,"<>")+COUNTIFS(Form127_Raw!$A$2:$A$1000,$A12,Form127_Raw!$F$2:$F$1000,">=2019",Form127_Raw!$F$2:$F$1000,"<=2024",Form127_Raw!$J$2:$J$1000,"<>")+COUNTIFS(Form127_Raw!$A$2:$A$1000,$A12,Form127_Raw!$F$2:$F$1000,">=2019",Form127_Raw!$F$2:$F$1000,"<=2024",Form127_Raw!$O$2:$O$1000,"<>")+COUNTIFS(Form127_Raw!$A$2:$A$1000,$A12,Form127_Raw!$F$2:$F$1000,">=2019",Form127_Raw!$F$2:$F$1000,"<=2024",Form127_Raw!$Q$2:$Q$1000,"<>")+COUNTIFS(Form127_Raw!$A$2:$A$1000,$A12,Form127_Raw!$F$2:$F$1000,">=2019",Form127_Raw!$F$2:$F$1000,"<=2024",Form127_Raw!$R$2:$R$1000,"<>"))/30 -> 0 | T12: =IF(D12=0,"Not Loaded",IF(R12>=0.9,IF(S12=1,"Ready for Final Selection","Excellent - FAA Backfill Pending"),IF(R12>=0.8,"Good - Review Missing Fields",IF(R12>=0.7,"Manual Review","Exclude / Incomplete")))) -> Excellent - FAA Backfill Pending
A13: =Airport_Master!A6 -> LAX | B13: =Airport_Master!B6 -> Los Angeles International | C13: =Airport_Master!E6 -> Large | D13: =COUNTIFS(Form127_Raw!$A$2:$A$1000,$A13,Form127_Raw!$F$2:$F$1000,">=2019",Form127_Raw!$F$2:$F$1000,"<=2024") -> 6 | E13: =D13/6 -> 1 | F13: =COUNTIFS(Form127_Raw!$A$2:$A$1000,$A13,Form127_Raw!$F$2:$F$1000,">=2019",Form127_Raw!$F$2:$F$1000,"<=2024",Form127_Raw!$G$2:$G$1000,"<>") -> 6 | G13: =COUNTIFS(Form127_Raw!$A$2:$A$1000,$A13,Form127_Raw!$F$2:$F$1000,">=2019",Form127_Raw!$F$2:$F$1000,"<=2024",Form127_Raw!$H$2:$H$1000,"<>") -> 6 | H13: =COUNTIFS(Form127_Raw!$A$2:$A$1000,$A13,Form127_Raw!$F$2:$F$1000,">=2019",Form127_Raw!$F$2:$F$1000,"<=2024",Form127_Raw!$S$2:$S$1000,"<>") -> 6 | I13: =COUNTIFS(Form127_Raw!$A$2:$A$1000,$A13,Form127_Raw!$F$2:$F$1000,">=2019",Form127_Raw!$F$2:$F$1000,"<=2024",Form127_Raw!$T$2:$T$1000,"<>") -> 6 | J13: =COUNTIFS(Form127_Raw!$A$2:$A$1000,$A13,Form127_Raw!$F$2:$F$1000,">=2019",Form127_Raw!$F$2:$F$1000,"<=2024",Form127_Raw!$N$2:$N$1000,"<>") -> 6 | K13: =COUNTIFS(Form127_Raw!$A$2:$A$1000,$A13,Form127_Raw!$F$2:$F$1000,">=2019",Form127_Raw!$F$2:$F$1000,"<=2024",Form127_Raw!$M$2:$M$1000,"<>") -> 6 | L13: =COUNTIFS(Form127_Raw!$A$2:$A$1000,$A13,Form127_Raw!$F$2:$F$1000,">=2019",Form127_Raw!$F$2:$F$1000,"<=2024",Form127_Raw!$K$2:$K$1000,"<>") -> 6 | M13: =COUNTIFS(Form127_Raw!$A$2:$A$1000,$A13,Form127_Raw!$F$2:$F$1000,">=2019",Form127_Raw!$F$2:$F$1000,"<=2024",Form127_Raw!$L$2:$L$1000,"<>") -> 6 | N13: =COUNTIFS(Form127_Raw!$A$2:$A$1000,$A13,Form127_Raw!$F$2:$F$1000,">=2019",Form127_Raw!$F$2:$F$1000,"<=2024",Form127_Raw!$P$2:$P$1000,"<>") -> 6 | O13: =SUM(F13:I13)/24 -> 1 | P13: =SUM(J13:N13)/30 -> 1 | Q13: =COUNTIFS(Form127_Raw!$A$2:$A$1000,$A13,Form127_Raw!$F$2:$F$1000,">=2019",Form127_Raw!$F$2:$F$1000,"<=2024",Form127_Raw!$N$2:$N$1000,0)+COUNTIFS(Form127_Raw!$A$2:$A$1000,$A13,Form127_Raw!$F$2:$F$1000,">=2019",Form127_Raw!$F$2:$F$1000,"<=2024",Form127_Raw!$M$2:$M$1000,0)+COUNTIFS(Form127_Raw!$A$2:$A$1000,$A13,Form127_Raw!$F$2:$F$1000,">=2019",Form127_Raw!$F$2:$F$1000,"<=2024",Form127_Raw!$K$2:$K$1000,0)+COUNTIFS(Form127_Raw!$A$2:$A$1000,$A13,Form127_Raw!$F$2:$F$1000,">=2019",Form127_Raw!$F$2:$F$1000,"<=2024",Form127_Raw!$L$2:$L$1000,0)+COUNTIFS(Form127_Raw!$A$2:$A$1000,$A13,Form127_Raw!$F$2:$F$1000,">=2019",Form127_Raw!$F$2:$F$1000,"<=2024",Form127_Raw!$P$2:$P$1000,0) -> 0 | R13: =O13*0.6+P13*0.4 -> 1 | S13: =(COUNTIFS(Form127_Raw!$A$2:$A$1000,$A13,Form127_Raw!$F$2:$F$1000,">=2019",Form127_Raw!$F$2:$F$1000,"<=2024",Form127_Raw!$I$2:$I$1000,"<>")+COUNTIFS(Form127_Raw!$A$2:$A$1000,$A13,Form127_Raw!$F$2:$F$1000,">=2019",Form127_Raw!$F$2:$F$1000,"<=2024",Form127_Raw!$J$2:$J$1000,"<>")+COUNTIFS(Form127_Raw!$A$2:$A$1000,$A13,Form127_Raw!$F$2:$F$1000,">=2019",Form127_Raw!$F$2:$F$1000,"<=2024",Form127_Raw!$O$2:$O$1000,"<>")+COUNTIFS(Form127_Raw!$A$2:$A$1000,$A13,Form127_Raw!$F$2:$F$1000,">=2019",Form127_Raw!$F$2:$F$1000,"<=2024",Form127_Raw!$Q$2:$Q$1000,"<>")+COUNTIFS(Form127_Raw!$A$2:$A$1000,$A13,Form127_Raw!$F$2:$F$1000,">=2019",Form127_Raw!$F$2:$F$1000,"<=2024",Form127_Raw!$R$2:$R$1000,"<>"))/30 -> 0 | T13: =IF(D13=0,"Not Loaded",IF(R13>=0.9,IF(S13=1,"Ready for Final Selection","Excellent - FAA Backfill Pending"),IF(R13>=0.8,"Good - Review Missing Fields",IF(R13>=0.7,"Manual Review","Exclude / Incomplete")))) -> Excellent - FAA Backfill Pending
A14: =Airport_Master!A7 -> JFK | B14: =Airport_Master!B7 -> John F Kennedy International | C14: =Airport_Master!E7 -> Large | D14: =COUNTIFS(Form127_Raw!$A$2:$A$1000,$A14,Form127_Raw!$F$2:$F$1000,">=2019",Form127_Raw!$F$2:$F$1000,"<=2024") -> 6 | E14: =D14/6 -> 1 | F14: =COUNTIFS(Form127_Raw!$A$2:$A$1000,$A14,Form127_Raw!$F$2:$F$1000,">=2019",Form127_Raw!$F$2:$F$1000,"<=2024",Form127_Raw!$G$2:$G$1000,"<>") -> 6 | G14: =COUNTIFS(Form127_Raw!$A$2:$A$1000,$A14,Form127_Raw!$F$2:$F$1000,">=2019",Form127_Raw!$F$2:$F$1000,"<=2024",Form127_Raw!$H$2:$H$1000,"<>") -> 6 | H14: =COUNTIFS(Form127_Raw!$A$2:$A$1000,$A14,Form127_Raw!$F$2:$F$1000,">=2019",Form127_Raw!$F$2:$F$1000,"<=2024",Form127_Raw!$S$2:$S$1000,"<>") -> 6 | I14: =COUNTIFS(Form127_Raw!$A$2:$A$1000,$A14,Form127_Raw!$F$2:$F$1000,">=2019",Form127_Raw!$F$2:$F$1000,"<=2024",Form127_Raw!$T$2:$T$1000,"<>") -> 6 | J14: =COUNTIFS(Form127_Raw!$A$2:$A$1000,$A14,Form127_Raw!$F$2:$F$1000,">=2019",Form127_Raw!$F$2:$F$1000,"<=2024",Form127_Raw!$N$2:$N$1000,"<>") -> 6 | K14: =COUNTIFS(Form127_Raw!$A$2:$A$1000,$A14,Form127_Raw!$F$2:$F$1000,">=2019",Form127_Raw!$F$2:$F$1000,"<=2024",Form127_Raw!$M$2:$M$1000,"<>") -> 6 | L14: =COUNTIFS(Form127_Raw!$A$2:$A$1000,$A14,Form127_Raw!$F$2:$F$1000,">=2019",Form127_Raw!$F$2:$F$1000,"<=2024",Form127_Raw!$K$2:$K$1000,"<>") -> 6 | M14: =COUNTIFS(Form127_Raw!$A$2:$A$1000,$A14,Form127_Raw!$F$2:$F$1000,">=2019",Form127_Raw!$F$2:$F$1000,"<=2024",Form127_Raw!$L$2:$L$1000,"<>") -> 6 | N14: =COUNTIFS(Form127_Raw!$A$2:$A$1000,$A14,Form127_Raw!$F$2:$F$1000,">=2019",Form127_Raw!$F$2:$F$1000,"<=2024",Form127_Raw!$P$2:$P$1000,"<>") -> 6 | O14: =SUM(F14:I14)/24 -> 1 | P14: =SUM(J14:N14)/30 -> 1 | Q14: =COUNTIFS(Form127_Raw!$A$2:$A$1000,$A14,Form127_Raw!$F$2:$F$1000,">=2019",Form127_Raw!$F$2:$F$1000,"<=2024",Form127_Raw!$N$2:$N$1000,0)+COUNTIFS(Form127_Raw!$A$2:$A$1000,$A14,Form127_Raw!$F$2:$F$1000,">=2019",Form127_Raw!$F$2:$F$1000,"<=2024",Form127_Raw!$M$2:$M$1000,0)+COUNTIFS(Form127_Raw!$A$2:$A$1000,$A14,Form127_Raw!$F$2:$F$1000,">=2019",Form127_Raw!$F$2:$F$1000,"<=2024",Form127_Raw!$K$2:$K$1000,0)+COUNTIFS(Form127_Raw!$A$2:$A$1000,$A14,Form127_Raw!$F$2:$F$1000,">=2019",Form127_Raw!$F$2:$F$1000,"<=2024",Form127_Raw!$L$2:$L$1000,0)+COUNTIFS(Form127_Raw!$A$2:$A$1000,$A14,Form127_Raw!$F$2:$F$1000,">=2019",Form127_Raw!$F$2:$F$1000,"<=2024",Form127_Raw!$P$2:$P$1000,0) -> 0 | R14: =O14*0.6+P14*0.4 -> 1 | S14: =(COUNTIFS(Form127_Raw!$A$2:$A$1000,$A14,Form127_Raw!$F$2:$F$1000,">=2019",Form127_Raw!$F$2:$F$1000,"<=2024",Form127_Raw!$I$2:$I$1000,"<>")+COUNTIFS(Form127_Raw!$A$2:$A$1000,$A14,Form127_Raw!$F$2:$F$1000,">=2019",Form127_Raw!$F$2:$F$1000,"<=2024",Form127_Raw!$J$2:$J$1000,"<>")+COUNTIFS(Form127_Raw!$A$2:$A$1000,$A14,Form127_Raw!$F$2:$F$1000,">=2019",Form127_Raw!$F$2:$F$1000,"<=2024",Form127_Raw!$O$2:$O$1000,"<>")+COUNTIFS(Form127_Raw!$A$2:$A$1000,$A14,Form127_Raw!$F$2:$F$1000,">=2019",Form127_Raw!$F$2:$F$1000,"<=2024",Form127_Raw!$Q$2:$Q$1000,"<>")+COUNTIFS(Form127_Raw!$A$2:$A$1000,$A14,Form127_Raw!$F$2:$F$1000,">=2019",Form127_Raw!$F$2:$F$1000,"<=2024",Form127_Raw!$R$2:$R$1000,"<>"))/30 -> 0 | T14: =IF(D14=0,"Not Loaded",IF(R14>=0.9,IF(S14=1,"Ready for Final Selection","Excellent - FAA Backfill Pending"),IF(R14>=0.8,"Good - Review Missing Fields",IF(R14>=0.7,"Manual Review","Exclude / Incomplete")))) -> Excellent - FAA Backfill Pending
